Workbook

Sheet Resumo
B1: Pontos | E1: Geral | I1: Ricardo | J1: 100
B2: Arrombado | E2: Arrombado Mor | F2: =B3 -> ANGELA | I2: LUCAS BABRIKOWSKI | J2: 100
A3: 1 | B3: =Angela!A1 -> ANGELA | C3: =Angela!E1 -> 84 | E3: Arrombado | F3: =B4 -> RAY | I3: WILL | J3: 100
A4: 2 | B4: =Ray!A1 -> RAY | C4: =Ray!E1 -> 74 | E4: Arrombadinho | F4: =B5 -> BOZSA | I4: Luan viado | J4: 100
A5: 3 | B5: =Bozsa!A1 -> BOZSA | C5: =Bozsa!E1 -> 63 | E5: Meta de pontuação | F5: 100 | I5: RAUL (Coveiro) | J5: 100
A6: 4 | B6: =Ricardo!A1 -> Ricardo (Coveiro) | C6: =Ricardo!E1 -> 61 | I6: BOZSA | J6: 100
A7: 5 | B7: =Raul!A1 -> RAUL (ex-Coveiro) | C7: =Raul!E1 -> 61 | I7: ANGELA | J7: 100
A8: 6 | B8: =Luan!A1 -> Luan viado | C8: =Luan!E1 -> 59 | I8: Bruno bizarro | J8: 100
A9: 7 | B9: ='Bruno bizarro'!A1 -> Bruno bizarro (letra ruim) | C9: ='Bruno bizarro'!E1 -> 59 | I9: RAY | J9: 100
A10: 8 | B10: =Will!A1 -> WILL | C10: =Will!E1 -> 58 | I10: Bruno Bacon | J10: 100
A11: 9 | B11: =Rayreis!A1 -> Ray satanista | C11: =Rayreis!E1 -> 50 | I11: Felipe | J11: 100
A12: 10 | B12: =pixote!A1 -> Pixote | C12: =pixote!E1 -> 50 | I12: 0 | J12: 100
A13: 11 | B13: =Felipe!A1 -> Felipe | C13: =Felipe!E1 -> 50 | I13: 0 | J13: 100
A14: 12 | B14: =Lucas!A1 -> Lucas aleatório | C14: =Lucas!E1 -> 24

Sheet Análises de arrombadisse
A1: Arrombado | B1: % Da meta | C1: % Do total
A2: =Resumo!B3 -> ANGELA | B2: =Resumo!C3/Resumo!$F$5 -> 0.84 | C2: =((100/sum(Resumo!C:C))*Resumo!C3)/100 -> 0.12121212
A3: =Resumo!B4 -> RAY | B3: =Resumo!C4/Resumo!$F$5 -> 0.74 | C3: =((100/sum(Resumo!C:C))*Resumo!C4)/100 -> 0.10678211
A4: =Resumo!B5 -> BOZSA | B4: =Resumo!C5/Resumo!$F$5 -> 0.63 | C4: =((100/sum(Resumo!C:C))*Resumo!C5)/100 -> 0.090909091
A5: =Resumo!B6 -> Ricardo (Coveiro) | B5: =Resumo!C6/Resumo!$F$5 -> 0.61 | C5: =((100/sum(Resumo!C:C))*Resumo!C6)/100 -> 0.088023088
A6: =Resumo!B7 -> RAUL (ex-Coveiro) | B6: =Resumo!C7/Resumo!$F$5 -> 0.61 | C6: =((100/sum(Resumo!C:C))*Resumo!C7)/100 -> 0.088023088
A7: =Resumo!B8 -> Luan viado | B7: =Resumo!C8/Resumo!$F$5 -> 0.59 | C7: =((100/sum(Resumo!C:C))*Resumo!C8)/100 -> 0.085137085
A8: =Resumo!B9 -> Bruno bizarro (letra ruim) | B8: =Resumo!C9/Resumo!$F$5 -> 0.59 | C8: =((100/sum(Resumo!C:C))*Resumo!C9)/100 -> 0.085137085
A9: =Resumo!B10 -> WILL | B9: =Resumo!C10/Resumo!$F$5 -> 0.58 | C9: =((100/sum(Resumo!C:C))*Resumo!C10)/100 -> 0.083694084
A10: =Resumo!B11 -> Ray satanista | B10: =Resumo!C11/Resumo!$F$5 -> 0.5 | C10: =((100/sum(Resumo!C:C))*Resumo!C11)/100 -> 0.072150072
A11: =Resumo!B12 -> Pixote | B11: =Resumo!C12/Resumo!$F$5 -> 0.5 | C11: =((100/sum(Resumo!C:C))*Resumo!C12)/100 -> 0.072150072
A12: =Resumo!B13 -> Felipe | B12: =Resumo!C13/Resumo!$F$5 -> 0.5 | C12: =((100/sum(Resumo!C:C))*Resumo!C13)/100 -> 0.072150072
A13: =Resumo!B14 -> Lucas aleatório | B13: =Resumo!C14/Resumo!$F$5 -> 0.24 | C13: =((100/sum(Resumo!C:C))*Resumo!C14)/100 -> 0.034632035

Sheet Resumo da morte

Sheet Angela
A1: ANGELA | D1: TOTAL | E1: =SUM(C:C) -> 84
A2: Nome | B2: Causa | C2: Pontuação
A3: fuad noman | B3: pneumonia | C3: 23
A4: Tony tornado | B4: parada cardiaca
A5: Preta Gil | B5: cancer | C5: 50
A6: Edgar vivar | B6: Parada cardio respiratoria
A7: Mama bruschetta | B7: pneumonia
A8: Ringo starr | B8: insuficiencea renal
A9: Warren beatty | B9: pneumonia
A10: Geoge w. bush | B10: FMO
A11: Laura cadoso | B11: Parada cardio respiratoria
A12: Milton nacimento | B12: AVC
A13: Yayoi kusama | B13: FMO
A14: Yoshiro tosashi | B14: FMO
A15: Tim rice
A16: Jose sarney
A17: Luiza erudina | B17: Embolia pulmonar
A18: Jose mujica | B18: cancer | C18: 11
A19: Cho seungyoun | B19: suicidio
A20: Phil collins | B20: Insuficiencia hepatica
A21: Yoko ono
A22: Mauricio de souza | B22: Parada cardio respiratoria

Sheet Rayreis
A1: Ray satanista | D1: TOTAL | E1: =SUM(C:C) -> 50
A2: Nome | B2: Causa | C2: Pontuação
A3: Raul gil | B3: causas naturais
A4: Lula | B4: acidendte domestico
A5: Gloria menezes | B5: CN
A6: tony rmos | B6: CN
A7: lima duarte | B7: CN
A8: moon taeil | B8: suicidio
A9: P diddy | B9: assassinado
A10: JK rowling | B10: doença
A11: jim carrey
A12: faustão | B12: fmo
A13: didi | B13: CN
A14: neil gayman | B14: suicidio
A15: Dinho ouro preto
A16: Andressa urach
A17: Preta Gil | C17: 50
A18: Yoon suk yeel | B18: suicidio
A19: Zizi pessi
A20: Joe biden | B20: CN
A21: leonardo cantor
A22: Maiaria da maraisa

Sheet Bruno bizarro
A1: Bruno bizarro (letra ruim) | D1: TOTAL | E1: =SUM(C:C) -> 59
A2: Nome | B2: Causa | C2: Pontuação
A3: lula
A4: bruce willis
A5: fernanda montenegro
A6: barbara streinsend
A7: mick jagger
A8: faustao
A9: toguro
A10: bolsonaro
A11: michal j fox
A12: christofer lloyd
A13: vicky vanilla
A14: Preta Gil | C14: 50
A15: jenna fischer
A16: rei charles
A17: ary fontura
A18: francisco cuoco | C18: 9
A19: celso portiollu
A20: kayky brito
A21: oruam
A22: leda nagle

Sheet Bozsa
A1: BOZSA | D1: TOTAL | E1: =SUM(C:C) -> 63
A2: Nome | B2: Causa | C2: Pontuação
A3: Lima Duarte | B3: Parada respiratória
A4: Laura Cardoso | B4: FMO
A5: Ary fontoura | B5: FMO
A6: Joan Plowright | C6: 4
A7: Preta Gil | C7: 50
A8: Ian Smith | B8: cancer
A9: Claudia rodrigues | B9: bronco aspiração
A10: Francisco cuoco | C10: 9
A11: Fernanda montenegro
A12: Nathalia timberg
A13: Barbara eoen
A14: Dede santana
A15: Gloria menezes
A16: Tiago leifert
A17: StenioGarcia
A18: Carlos alberto de nobrega
A19: Paulinho da viola
A20: Thais carla
A21: Ringo Star
A22: Diana ross

Sheet Felipe
A1: Felipe | D1: TOTAL | E1: =SUM(C:C) -> 50
A2: Nome | B2: Causa | C2: Pontuação
A3: Renato aragão | B3: AVC
A4: Felipe castanhari | B4: suicidio
A5: Laura cardoso | B5: AVC
A6: Lima duarte | B6: AVC
A7: Ary fontura | B7: AVC
A8: Preta Gil | B8: Cancer | C8: 50
A9: Gilberto gil | B9: FMO
A10: Nicolas cage | B10: parada cardiaca
A11: Paul mccartney
A12: Lula | B12: Hemorragia
A13: Phill collin | B13: AVC
A14: Celine dion | B14: FMC
A15: Rod stewart | B15: cancer
A16: Roberto carlos (rei) | B16: AVC
A17: Madonna | B17: Parada cardiaca
A18: Ney matogrosso | B18: Parada cardiaca
A19: Sérgio reis | B19: Parada cardiaca
A20: Gustavo lima | B20: assassinado
A21: Bolsonaro | B21: assassinado
A22: Moacyr franco | B22: Aneurisma

Sheet Luan
A1: Luan viado | D1: TOTAL | E1: =SUM(C:C) -> 59
A2: Nome | B2: Causa | C2: Pontuação
A3: Fernanda montenegro | B3: iam
A4: faustao | B4: icc
A5: lima duarte | B5: avc
A6: tony tornando | B6: cancer
A7: ary fontura | B7: pneumonia
A8: nathalia tiberge | B8: ICE
A9: laura cardoso | B9: dormindo
A10: jose arney | B10: pneumonia
A11: Lula | B11: avc
A12: fhc | B12: icc
A13: maluf | B13: iam
A14: jose serra | B14: cancer
... A16: Gloia menezes | B16: hemorragia
A17: Preta Gil | B17: cancer | C17: 50
A18: francisco cuoco | B18: iam | C18: 9
A19: leda nagle | B19: avc
A20: lua leifert | B20: cancer
A21: othan bastos | B21: icc
A22: steno garcia | B22: avc

Sheet Ray
A1: RAY | D1: TOTAL | E1: =SUM(C:C) -> 74
A2: Nome | B2: Causa | C2: Pontuação
A3: Roberto carlos | B3: AVC
A4: Renan calheiras
A5: Carlos alberto
A6: Ozzy osbourne | B6: queda | C6: 24
A7: Monark | B7: suicidio
A8: Preta Gil | B8: cancer | C8: 50
A9: Lima duarte
A10: Stenio garcia
A11: Keith Richards
A12: fernanda montenegro
A13: Ben affleck
A14: Mama bruschetta | B14: pneumonia
A15: Isabel veloso
A16: FHC
A17: Morgan freeman
A18: sergio reis
A19: rod stewart
A20: sophia loren
A21: laura cardoso
A22: gloria menezes

Sheet Raul
A1: RAUL (ex-Coveiro) | D1: TOTAL | E1: =SUM(C:C) -> 61
A2: Nome | B2: Causa | C2: Pontuação
A3: Carlos alberto | B3: bateu a cabeça
A4: M schumacker
A5: Tom cruise | B5: AVC
A6: Bruce willis
A7: Bonner | B7: Infarto
A8: Didi
A9: Lima duarte | B9: Engagado com melão
A10: Bruno do marrone
A11: Preta Gil | B11: comida | C11: 50
A12: Raul gil | B12: Infarto
A13: Ary fontura
A14: Paul maccartney
A15: Roberto carlos (rei)
A16: Sergio reis
A17: Faustão | B17: infarto
A18: Susana vieira
A19: Ana maria braga | B19: ataque de cães
A20: Emilio surita
A21: Jose mujica | C21: 11
A22: Casa grande

Sheet Ricardo
A1: Ricardo (Coveiro) | D1: TOTAL | E1: =SUM(C:C) -> 61
A2: Nome | B2: Causa | C2: Pontuação
A3: Michael schumacker | B3: FMO
A4: boris casoy | B4: complicações respiratórias
A5: Isabel veloso | B5: FMO
A6: Faustão | B6: parada cardiorespiratória
A7: Jose mujica | B7: pcr | C7: 11
A8: claudia rodrigues | B8: fmo
A9: marcos oliveira | B9: suicidio
A10: tony tornado | B10: causas naturais
A11: Datena | B11: infarno
A12: Carlos alberto | B12: AVC
A13: Calminha | B13: queda de moto
A14: Nino abavanel | B14: traumatismo
A15: mama bruschetta | B15: avc
A16: Preta Gil | B16: complicações do cancer | C16: 50
A17: sergio reis | B17: fibrilação atuial
A18: lima duarte | B18: causas naturais
A19: tjairzinho | B19: infarto
A20: yoshino togashi | B20: linfoma
A21: Ary fontoura | B21: causas naturais
A22: Milionário do josé rico | B22: infarto

Sheet Will
A1: WILL | D1: TOTAL | E1: =SUM(C:C) -> 58
A2: Nome | B2: Causa | C2: Pontuação
A3: Faustao | B3: AVC
A4: Volodymyr zelensky | B4: suicidio suspeito
A5: Sarney | B5: Nova pandemia asiatica
A6: Monark | B6: suicidio suspeito
A7: alek do zoio | B7: assassinado
A8: Pepe mijica | B8: tosse de cachorro veio | C8: 11
A9: Gilberto gil
A10: Schumacher | B10: desligaram o aparelho
A11: fuad noman | B11: desligaram o aparelho | C11: 23
A12: fhc | B12: bacteria no estomago
A13: claudio rodrigues | B13: acidente domestico
A14: Ozzy osbourne | B14: desligaram o aparelho | C14: 24
A15: fernanda montenegro
A16: raul gil
A17: roberto carlos | B17: caiu do palco
A18: lima duarte | B18: ataque cardiaco
A19: Carlos alberto | B19: avc
A20: gloria menezes | B20: pneumonia
A21: isabel veloso | B21: fmo
A22: Andressa urach

Sheet pixote
A1: Pixote | D1: TOTAL | E1: =SUM(C:C) -> 50
A2: Nome | B2: Causa | C2: Pontuação
A3: Lula | B3: AVC
A4: Suzana vieira | B4: leucemia
A5: Preta Gil | B5: cancer | C5: 50
A6: faustão
A7: simony | B7: cancer
A8: mauricio kubrosly | B8: falencia do cerebro
A9: fernanda monte negro
A10: bruce willis | B10: falencia celebral
A11: laura cardoso
A12: thais carla | B12: cirurgia
A13: lima duarte
A14: ary fontura | B14: fmo
A15: kabrinha | B15: acidente
A16: elton john
A17: raul gil
A18: gordao da xj | B18: cirurgia
A19: day z | B19: assassinato
A20: liluzi | B20: overdose
A21: fernando do sorocaba | B21: acidente
A22: bolsonaro | B22: assassinato

Sheet Lucas
A1: Lucas aleatório | D1: TOTAL | E1: =SUM(C:C) -> 24
A2: Nome | B2: Causa | C2: Pontuação
A3: P diddy
A4: jackie chan
A5: putin | B5: missil
A6: Biden
A7: Papa francisco | B7: AVC | C7: 24
A8: Aecio neves
A9: trump
A10: arthur do val | B10: assasinato a mao armada
A11: silas malafaia | B11: engasgado
A12: RR Soares
A13: bolsonaro | B13: intestino
A14: Padre kelmon
A15: ricardo salles
A16: edir macedo
A17: valdemiro santiago
A18: michael tamer
A19: Eduardo bolsonaro
A20: marco feliciano
A21: tarcisiio

Sheet Alvos
A1: Alvos | B1: Acertou | C1: Data morte
A2: =IFERROR(__xludf.DUMMYFUNCTION("FILTER(UNIQUE(FLATTEN(Angela!A3:A5506,Rayreis!A3:A5506,'Bruno bizarro'!A3:A5506,Bozsa!A3:A5506,Felipe!A3:A5506,Luan!A3:A5506,Ray!A3:A5506,Raul!A3:A5506,Ricardo!A3:A5506,pixote!A3:A5506,Lucas!A3:A5506,Will!A3:A5506)), NOT(ISBLANK(UNIQUE(FLATTEN(Angela!A3:A"&"5506,Rayreis!A3:A5506,'Bruno bizarro'!A3:A5506,Bozsa!A3:A5506,Felipe!A3:A5506,Luan!A3:A5506,Ray!A3:A5506,Raul!A3:A5506,Ricardo!A3:A5506,pixote!A3:A5506,Lucas!A3:A5506,Will!A3:A5506)))))"),"fuad noman") -> fuad noman | B2: =TEXTJOIN(", ", TRUE, IF(COUNTIF(Angela!$A$3:$A$5506, A2), Angela!$A$1, ), IF(COUNTIF(Rayreis!$A$3:$A$5506, A2), Rayreis!$A$1, ), IF(COUNTIF('Bruno bizarro'!$A$3:$A$5506, A2), 'Bruno bizarro'!$A$1, ), IF(COUNTIF(Bozsa!$A$3:$A$5506, A2), Bozsa!$A$1, ), IF(COUNTIF(Felipe!$A$3:$A$5506, A2), Felipe!$A$1, ), IF(COUNTIF(Luan!$A$3:$A$5506, A2), Luan!$A$1, ), IF(COUNTIF(Ray!$A$3:$A$5506, A2), Ray!$A$1, ), IF(COUNTIF(Raul!$A$3:$A$5506, A2), Raul!$A$1, ), IF(COUNTIF(Ricardo!$A$3:$A$5506, A2), Ricardo!$A$1, ), IF(COUNTIF(pixote!$A$3:$A$5506, A2), pixote!$A$1, ), IF(COUNTIF(Lucas!$A$3:$A$5506, A2), Lucas!$A$1, ), IF(COUNTIF(Will!$A$3:$A$5506, A2), Will!$A$1, ) ) -> ANGELA, WILL | C2: 26 de março de 2025
A3: =IFERROR(__xludf.DUMMYFUNCTION("""COMPUTED_VALUE"""),"Tony tornado") -> Tony tornado | B3: =TEXTJOIN(", ", TRUE, IF(COUNTIF(Angela!$A$3:$A$5506, A3), Angela!$A$1, ), IF(COUNTIF(Rayreis!$A$3:$A$5506, A3), Rayreis!$A$1, ), IF(COUNTIF('Bruno bizarro'!$A$3:$A$5506, A3), 'Bruno bizarro'!$A$1, ), IF(COUNTIF(Bozsa!$A$3:$A$5506, A3), Bozsa!$A$1, ), IF(COUNTIF(Felipe!$A$3:$A$5506, A3), Felipe!$A$1, ), IF(COUNTIF(Luan!$A$3:$A$5506, A3), Luan!$A$1, ), IF(COUNTIF(Ray!$A$3:$A$5506, A3), Ray!$A$1, ), IF(COUNTIF(Raul!$A$3:$A$5506, A3), Raul!$A$1, ), IF(COUNTIF(Ricardo!$A$3:$A$5506, A3), Ricardo!$A$1, ), IF(COUNTIF(pixote!$A$3:$A$5506, A3), pixote!$A$1, ), IF(COUNTIF(Lucas!$A$3:$A$5506, A3), Lucas!$A$1, ), IF(COUNTIF(Will!$A$3:$A$5506, A3), Will!$A$1, ) ) -> ANGELA, Ricardo (Coveiro)
A4: =IFERROR(__xludf.DUMMYFUNCTION("""COMPUTED_VALUE"""),"Preta Gil") -> Preta Gil | B4: =TEXTJOIN(", ", TRUE, IF(COUNTIF(Angela!$A$3:$A$5506, A4), Angela!$A$1, ), IF(COUNTIF(Rayreis!$A$3:$A$5506, A4), Rayreis!$A$1, ), IF(COUNTIF('Bruno bizarro'!$A$3:$A$5506, A4), 'Bruno bizarro'!$A$1, ), IF(COUNTIF(Bozsa!$A$3:$A$5506, A4), Bozsa!$A$1, ), IF(COUNTIF(Felipe!$A$3:$A$5506, A4), Felipe!$A$1, ), IF(COUNTIF(Luan!$A$3:$A$5506, A4), Luan!$A$1, ), IF(COUNTIF(Ray!$A$3:$A$5506, A4), Ray!$A$1, ), IF(COUNTIF(Raul!$A$3:$A$5506, A4), Raul!$A$1, ), IF(COUNTIF(Ricardo!$A$3:$A$5506, A4), Ricardo!$A$1, ), IF(COUNTIF(pixote!$A$3:$A$5506, A4), pixote!$A$1, ), IF(COUNTIF(Lucas!$A$3:$A$5506, A4), Lucas!$A$1, ), IF(COUNTIF(Will!$A$3:$A$5506, A4), Will!$A$1, ) ) -> ANGELA, Ray satanista, Bruno bizarro (letra ruim), BOZSA, Felipe, Luan viado, RAY, RAUL (ex-Coveiro) , Ricardo (Coveiro), Pixote | C4: 20 de julho de 2025
A5: =IFERROR(__xludf.DUMMYFUNCTION("""COMPUTED_VALUE"""),"Edgar vivar") -> Edgar vivar | B5: =TEXTJOIN(", ", TRUE, IF(COUNTIF(Angela!$A$3:$A$5506, A5), Angela!$A$1, ), IF(COUNTIF(Rayreis!$A$3:$A$5506, A5), Rayreis!$A$1, ), IF(COUNTIF('Bruno bizarro'!$A$3:$A$5506, A5), 'Bruno bizarro'!$A$1, ), IF(COUNTIF(Bozsa!$A$3:$A$5506, A5), Bozsa!$A$1, ), IF(COUNTIF(Felipe!$A$3:$A$5506, A5), Felipe!$A$1, ), IF(COUNTIF(Luan!$A$3:$A$5506, A5), Luan!$A$1, ), IF(COUNTIF(Ray!$A$3:$A$5506, A5), Ray!$A$1, ), IF(COUNTIF(Raul!$A$3:$A$5506, A5), Raul!$A$1, ), IF(COUNTIF(Ricardo!$A$3:$A$5506, A5), Ricardo!$A$1, ), IF(COUNTIF(pixote!$A$3:$A$5506, A5), pixote!$A$1, ), IF(COUNTIF(Lucas!$A$3:$A$5506, A5), Lucas!$A$1, ), IF(COUNTIF(Will!$A$3:$A$5506, A5), Will!$A$1, ) ) -> ANGELA
A6: =IFERROR(__xludf.DUMMYFUNCTION("""COMPUTED_VALUE"""),"Mama bruschetta") -> Mama bruschetta | B6: =TEXTJOIN(", ", TRUE, IF(COUNTIF(Angela!$A$3:$A$5506, A6), Angela!$A$1, ), IF(COUNTIF(Rayreis!$A$3:$A$5506, A6), Rayreis!$A$1, ), IF(COUNTIF('Bruno bizarro'!$A$3:$A$5506, A6), 'Bruno bizarro'!$A$1, ), IF(COUNTIF(Bozsa!$A$3:$A$5506, A6), Bozsa!$A$1, ), IF(COUNTIF(Felipe!$A$3:$A$5506, A6), Felipe!$A$1, ), IF(COUNTIF(Luan!$A$3:$A$5506, A6), Luan!$A$1, ), IF(COUNTIF(Ray!$A$3:$A$5506, A6), Ray!$A$1, ), IF(COUNTIF(Raul!$A$3:$A$5506, A6), Raul!$A$1, ), IF(COUNTIF(Ricardo!$A$3:$A$5506, A6), Ricardo!$A$1, ), IF(COUNTIF(pixote!$A$3:$A$5506, A6), pixote!$A$1, ), IF(COUNTIF(Lucas!$A$3:$A$5506, A6), Lucas!$A$1, ), IF(COUNTIF(Will!$A$3:$A$5506, A6), Will!$A$1, ) ) -> ANGELA, RAY, Ricardo (Coveiro)
A7: =IFERROR(__xludf.DUMMYFUNCTION("""COMPUTED_VALUE"""),"Ringo starr") -> Ringo starr | B7: =TEXTJOIN(", ", TRUE, IF(COUNTIF(Angela!$A$3:$A$5506, A7), Angela!$A$1, ), IF(COUNTIF(Rayreis!$A$3:$A$5506, A7), Rayreis!$A$1, ), IF(COUNTIF('Bruno bizarro'!$A$3:$A$5506, A7), 'Bruno bizarro'!$A$1, ), IF(COUNTIF(Bozsa!$A$3:$A$5506, A7), Bozsa!$A$1, ), IF(COUNTIF(Felipe!$A$3:$A$5506, A7), Felipe!$A$1, ), IF(COUNTIF(Luan!$A$3:$A$5506, A7), Luan!$A$1, ), IF(COUNTIF(Ray!$A$3:$A$5506, A7), Ray!$A$1, ), IF(COUNTIF(Raul!$A$3:$A$5506, A7), Raul!$A$1, ), IF(COUNTIF(Ricardo!$A$3:$A$5506, A7), Ricardo!$A$1, ), IF(COUNTIF(pixote!$A$3:$A$5506, A7), pixote!$A$1, ), IF(COUNTIF(Lucas!$A$3:$A$5506, A7), Lucas!$A$1, ), IF(COUNTIF(Will!$A$3:$A$5506, A7), Will!$A$1, ) ) -> ANGELA
A8: =IFERROR(__xludf.DUMMYFUNCTION("""COMPUTED_VALUE"""),"Warren beatty") -> Warren beatty | B8: =TEXTJOIN(", ", TRUE, IF(COUNTIF(Angela!$A$3:$A$5506, A8), Angela!$A$1, ), IF(COUNTIF(Rayreis!$A$3:$A$5506, A8), Rayreis!$A$1, ), IF(COUNTIF('Bruno bizarro'!$A$3:$A$5506, A8), 'Bruno bizarro'!$A$1, ), IF(COUNTIF(Bozsa!$A$3:$A$5506, A8), Bozsa!$A$1, ), IF(COUNTIF(Felipe!$A$3:$A$5506, A8), Felipe!$A$1, ), IF(COUNTIF(Luan!$A$3:$A$5506, A8), Luan!$A$1, ), IF(COUNTIF(Ray!$A$3:$A$5506, A8), Ray!$A$1, ), IF(COUNTIF(Raul!$A$3:$A$5506, A8), Raul!$A$1, ), IF(COUNTIF(Ricardo!$A$3:$A$5506, A8), Ricardo!$A$1, ), IF(COUNTIF(pixote!$A$3:$A$5506, A8), pixote!$A$1, ), IF(COUNTIF(Lucas!$A$3:$A$5506, A8), Lucas!$A$1, ), IF(COUNTIF(Will!$A$3:$A$5506, A8), Will!$A$1, ) ) -> ANGELA
A9: =IFERROR(__xludf.DUMMYFUNCTION("""COMPUTED_VALUE"""),"Geoge w. bush") -> Geoge w. bush | B9: =TEXTJOIN(", ", TRUE, IF(COUNTIF(Angela!$A$3:$A$5506, A9), Angela!$A$1, ), IF(COUNTIF(Rayreis!$A$3:$A$5506, A9), Rayreis!$A$1, ), IF(COUNTIF('Bruno bizarro'!$A$3:$A$5506, A9), 'Bruno bizarro'!$A$1, ), IF(COUNTIF(Bozsa!$A$3:$A$5506, A9), Bozsa!$A$1, ), IF(COUNTIF(Felipe!$A$3:$A$5506, A9), Felipe!$A$1, ), IF(COUNTIF(Luan!$A$3:$A$5506, A9), Luan!$A$1, ), IF(COUNTIF(Ray!$A$3:$A$5506, A9), Ray!$A$1, ), IF(COUNTIF(Raul!$A$3:$A$5506, A9), Raul!$A$1, ), IF(COUNTIF(Ricardo!$A$3:$A$5506, A9), Ricardo!$A$1, ), IF(COUNTIF(pixote!$A$3:$A$5506, A9), pixote!$A$1, ), IF(COUNTIF(Lucas!$A$3:$A$5506, A9), Lucas!$A$1, ), IF(COUNTIF(Will!$A$3:$A$5506, A9), Will!$A$1, ) ) -> ANGELA
A10: =IFERROR(__xludf.DUMMYFUNCTION("""COMPUTED_VALUE"""),"Laura cadoso") -> Laura cadoso | B10: =TEXTJOIN(", ", TRUE, IF(COUNTIF(Angela!$A$3:$A$5506, A10), Angela!$A$1, ), IF(COUNTIF(Rayreis!$A$3:$A$5506, A10), Rayreis!$A$1, ), IF(COUNTIF('Bruno bizarro'!$A$3:$A$5506, A10), 'Bruno bizarro'!$A$1, ), IF(COUNTIF(Bozsa!$A$3:$A$5506, A10), Bozsa!$A$1, ), IF(COUNTIF(Felipe!$A$3:$A$5506, A10), Felipe!$A$1, ), IF(COUNTIF(Luan!$A$3:$A$5506, A10), Luan!$A$1, ), IF(COUNTIF(Ray!$A$3:$A$5506, A10), Ray!$A$1, ), IF(COUNTIF(Raul!$A$3:$A$5506, A10), Raul!$A$1, ), IF(COUNTIF(Ricardo!$A$3:$A$5506, A10), Ricardo!$A$1, ), IF(COUNTIF(pixote!$A$3:$A$5506, A10), pixote!$A$1, ), IF(COUNTIF(Lucas!$A$3:$A$5506, A10), Lucas!$A$1, ), IF(COUNTIF(Will!$A$3:$A$5506, A10), Will!$A$1, ) ) -> ANGELA
A11: =IFERROR(__xludf.DUMMYFUNCTION("""COMPUTED_VALUE"""),"Milton nacimento") -> Milton nacimento | B11: =TEXTJOIN(", ", TRUE, IF(COUNTIF(Angela!$A$3:$A$5506, A11), Angela!$A$1, ), IF(COUNTIF(Rayreis!$A$3:$A$5506, A11), Rayreis!$A$1, ), IF(COUNTIF('Bruno bizarro'!$A$3:$A$5506, A11), 'Bruno bizarro'!$A$1, ), IF(COUNTIF(Bozsa!$A$3:$A$5506, A11), Bozsa!$A$1, ), IF(COUNTIF(Felipe!$A$3:$A$5506, A11), Felipe!$A$1, ), IF(COUNTIF(Luan!$A$3:$A$5506, A11), Luan!$A$1, ), IF(COUNTIF(Ray!$A$3:$A$5506, A11), Ray!$A$1, ), IF(COUNTIF(Raul!$A$3:$A$5506, A11), Raul!$A$1, ), IF(COUNTIF(Ricardo!$A$3:$A$5506, A11), Ricardo!$A$1, ), IF(COUNTIF(pixote!$A$3:$A$5506, A11), pixote!$A$1, ), IF(COUNTIF(Lucas!$A$3:$A$5506, A11), Lucas!$A$1, ), IF(COUNTIF(Will!$A$3:$A$5506, A11), Will!$A$1, ) ) -> ANGELA
A12: =IFERROR(__xludf.DUMMYFUNCTION("""COMPUTED_VALUE"""),"Yayoi kusama") -> Yayoi kusama | B12: =TEXTJOIN(", ", TRUE, IF(COUNTIF(Angela!$A$3:$A$5506, A12), Angela!$A$1, ), IF(COUNTIF(Rayreis!$A$3:$A$5506, A12), Rayreis!$A$1, ), IF(COUNTIF('Bruno bizarro'!$A$3:$A$5506, A12), 'Bruno bizarro'!$A$1, ), IF(COUNTIF(Bozsa!$A$3:$A$5506, A12), Bozsa!$A$1, ), IF(COUNTIF(Felipe!$A$3:$A$5506, A12), Felipe!$A$1, ), IF(COUNTIF(Luan!$A$3:$A$5506, A12), Luan!$A$1, ), IF(COUNTIF(Ray!$A$3:$A$5506, A12), Ray!$A$1, ), IF(COUNTIF(Raul!$A$3:$A$5506, A12), Raul!$A$1, ), IF(COUNTIF(Ricardo!$A$3:$A$5506, A12), Ricardo!$A$1, ), IF(COUNTIF(pixote!$A$3:$A$5506, A12), pixote!$A$1, ), IF(COUNTIF(Lucas!$A$3:$A$5506, A12), Lucas!$A$1, ), IF(COUNTIF(Will!$A$3:$A$5506, A12), Will!$A$1, ) ) -> ANGELA
A13: =IFERROR(__xludf.DUMMYFUNCTION("""COMPUTED_VALUE"""),"Yoshiro tosashi") -> Yoshiro tosashi | B13: =TEXTJOIN(", ", TRUE, IF(COUNTIF(Angela!$A$3:$A$5506, A13), Angela!$A$1, ), IF(COUNTIF(Rayreis!$A$3:$A$5506, A13), Rayreis!$A$1, ), IF(COUNTIF('Bruno bizarro'!$A$3:$A$5506, A13), 'Bruno bizarro'!$A$1, ), IF(COUNTIF(Bozsa!$A$3:$A$5506, A13), Bozsa!$A$1, ), IF(COUNTIF(Felipe!$A$3:$A$5506, A13), Felipe!$A$1, ), IF(COUNTIF(Luan!$A$3:$A$5506, A13), Luan!$A$1, ), IF(COUNTIF(Ray!$A$3:$A$5506, A13), Ray!$A$1, ), IF(COUNTIF(Raul!$A$3:$A$5506, A13), Raul!$A$1, ), IF(COUNTIF(Ricardo!$A$3:$A$5506, A13), Ricardo!$A$1, ), IF(COUNTIF(pixote!$A$3:$A$5506, A13), pixote!$A$1, ), IF(COUNTIF(Lucas!$A$3:$A$5506, A13), Lucas!$A$1, ), IF(COUNTIF(Will!$A$3:$A$5506, A13), Will!$A$1, ) ) -> ANGELA
A14: =IFERROR(__xludf.DUMMYFUNCTION("""COMPUTED_VALUE"""),"Tim rice") -> Tim rice | B14: =TEXTJOIN(", ", TRUE, IF(COUNTIF(Angela!$A$3:$A$5506, A14), Angela!$A$1, ), IF(COUNTIF(Rayreis!$A$3:$A$5506, A14), Rayreis!$A$1, ), IF(COUNTIF('Bruno bizarro'!$A$3:$A$5506, A14), 'Bruno bizarro'!$A$1, ), IF(COUNTIF(Bozsa!$A$3:$A$5506, A14), Bozsa!$A$1, ), IF(COUNTIF(Felipe!$A$3:$A$5506, A14), Felipe!$A$1, ), IF(COUNTIF(Luan!$A$3:$A$5506, A14), Luan!$A$1, ), IF(COUNTIF(Ray!$A$3:$A$5506, A14), Ray!$A$1, ), IF(COUNTIF(Raul!$A$3:$A$5506, A14), Raul!$A$1, ), IF(COUNTIF(Ricardo!$A$3:$A$5506, A14), Ricardo!$A$1, ), IF(COUNTIF(pixote!$A$3:$A$5506, A14), pixote!$A$1, ), IF(COUNTIF(Lucas!$A$3:$A$5506, A14), Lucas!$A$1, ), IF(COUNTIF(Will!$A$3:$A$5506, A14), Will!$A$1, ) ) -> ANGELA
A15: =IFERROR(__xludf.DUMMYFUNCTION("""COMPUTED_VALUE"""),"Jose sarney") -> Jose sarney | B15: =TEXTJOIN(", ", TRUE, IF(COUNTIF(Angela!$A$3:$A$5506, A15), Angela!$A$1, ), IF(COUNTIF(Rayreis!$A$3:$A$5506, A15), Rayreis!$A$1, ), IF(COUNTIF('Bruno bizarro'!$A$3:$A$5506, A15), 'Bruno bizarro'!$A$1, ), IF(COUNTIF(Bozsa!$A$3:$A$5506, A15), Bozsa!$A$1, ), IF(COUNTIF(Felipe!$A$3:$A$5506, A15), Felipe!$A$1, ), IF(COUNTIF(Luan!$A$3:$A$5506, A15), Luan!$A$1, ), IF(COUNTIF(Ray!$A$3:$A$5506, A15), Ray!$A$1, ), IF(COUNTIF(Raul!$A$3:$A$5506, A15), Raul!$A$1, ), IF(COUNTIF(Ricardo!$A$3:$A$5506, A15), Ricardo!$A$1, ), IF(COUNTIF(pixote!$A$3:$A$5506, A15), pixote!$A$1, ), IF(COUNTIF(Lucas!$A$3:$A$5506, A15), Lucas!$A$1, ), IF(COUNTIF(Will!$A$3:$A$5506, A15), Will!$A$1, ) ) -> ANGELA
A16: =IFERROR(__xludf.DUMMYFUNCTION("""COMPUTED_VALUE"""),"Luiza erudina") -> Luiza erudina | B16: =TEXTJOIN(", ", TRUE, IF(COUNTIF(Angela!$A$3:$A$5506, A16), Angela!$A$1, ), IF(COUNTIF(Rayreis!$A$3:$A$5506, A16), Rayreis!$A$1, ), IF(COUNTIF('Bruno bizarro'!$A$3:$A$5506, A16), 'Bruno bizarro'!$A$1, ), IF(COUNTIF(Bozsa!$A$3:$A$5506, A16), Bozsa!$A$1, ), IF(COUNTIF(Felipe!$A$3:$A$5506, A16), Felipe!$A$1, ), IF(COUNTIF(Luan!$A$3:$A$5506, A16), Luan!$A$1, ), IF(COUNTIF(Ray!$A$3:$A$5506, A16), Ray!$A$1, ), IF(COUNTIF(Raul!$A$3:$A$5506, A16), Raul!$A$1, ), IF(COUNTIF(Ricardo!$A$3:$A$5506, A16), Ricardo!$A$1, ), IF(COUNTIF(pixote!$A$3:$A$5506, A16), pixote!$A$1, ), IF(COUNTIF(Lucas!$A$3:$A$5506, A16), Lucas!$A$1, ), IF(COUNTIF(Will!$A$3:$A$5506, A16), Will!$A$1, ) ) -> ANGELA
A17: =IFERROR(__xludf.DUMMYFUNCTION("""COMPUTED_VALUE"""),"Jose mujica") -> Jose mujica | B17: =TEXTJOIN(", ", TRUE, IF(COUNTIF(Angela!$A$3:$A$5506, A17), Angela!$A$1, ), IF(COUNTIF(Rayreis!$A$3:$A$5506, A17), Rayreis!$A$1, ), IF(COUNTIF('Bruno bizarro'!$A$3:$A$5506, A17), 'Bruno bizarro'!$A$1, ), IF(COUNTIF(Bozsa!$A$3:$A$5506, A17), Bozsa!$A$1, ), IF(COUNTIF(Felipe!$A$3:$A$5506, A17), Felipe!$A$1, ), IF(COUNTIF(Luan!$A$3:$A$5506, A17), Luan!$A$1, ), IF(COUNTIF(Ray!$A$3:$A$5506, A17), Ray!$A$1, ), IF(COUNTIF(Raul!$A$3:$A$5506, A17), Raul!$A$1, ), IF(COUNTIF(Ricardo!$A$3:$A$5506, A17), Ricardo!$A$1, ), IF(COUNTIF(pixote!$A$3:$A$5506, A17), pixote!$A$1, ), IF(COUNTIF(Lucas!$A$3:$A$5506, A17), Lucas!$A$1, ), IF(COUNTIF(Will!$A$3:$A$5506, A17), Will!$A$1, ) ) -> ANGELA, RAUL (ex-Coveiro) , Ricardo (Coveiro) | C17: 13 de maio de 2025
A18: =IFERROR(__xludf.DUMMYFUNCTION("""COMPUTED_VALUE"""),"Cho seungyoun") -> Cho seungyoun | B18: =TEXTJOIN(", ", TRUE, IF(COUNTIF(Angela!$A$3:$A$5506, A18), Angela!$A$1, ), IF(COUNTIF(Rayreis!$A$3:$A$5506, A18), Rayreis!$A$1, ), IF(COUNTIF('Bruno bizarro'!$A$3:$A$5506, A18), 'Bruno bizarro'!$A$1, ), IF(COUNTIF(Bozsa!$A$3:$A$5506, A18), Bozsa!$A$1, ), IF(COUNTIF(Felipe!$A$3:$A$5506, A18), Felipe!$A$1, ), IF(COUNTIF(Luan!$A$3:$A$5506, A18), Luan!$A$1, ), IF(COUNTIF(Ray!$A$3:$A$5506, A18), Ray!$A$1, ), IF(COUNTIF(Raul!$A$3:$A$5506, A18), Raul!$A$1, ), IF(COUNTIF(Ricardo!$A$3:$A$5506, A18), Ricardo!$A$1, ), IF(COUNTIF(pixote!$A$3:$A$5506, A18), pixote!$A$1, ), IF(COUNTIF(Lucas!$A$3:$A$5506, A18), Lucas!$A$1, ), IF(COUNTIF(Will!$A$3:$A$5506, A18), Will!$A$1, ) ) -> ANGELA
A19: =IFERROR(__xludf.DUMMYFUNCTION("""COMPUTED_VALUE"""),"Phil collins") -> Phil collins | B19: =TEXTJOIN(", ", TRUE, IF(COUNTIF(Angela!$A$3:$A$5506, A19), Angela!$A$1, ), IF(COUNTIF(Rayreis!$A$3:$A$5506, A19), Rayreis!$A$1, ), IF(COUNTIF('Bruno bizarro'!$A$3:$A$5506, A19), 'Bruno bizarro'!$A$1, ), IF(COUNTIF(Bozsa!$A$3:$A$5506, A19), Bozsa!$A$1, ), IF(COUNTIF(Felipe!$A$3:$A$5506, A19), Felipe!$A$1, ), IF(COUNTIF(Luan!$A$3:$A$5506, A19), Luan!$A$1, ), IF(COUNTIF(Ray!$A$3:$A$5506, A19), Ray!$A$1, ), IF(COUNTIF(Raul!$A$3:$A$5506, A19), Raul!$A$1, ), IF(COUNTIF(Ricardo!$A$3:$A$5506, A19), Ricardo!$A$1, ), IF(COUNTIF(pixote!$A$3:$A$5506, A19), pixote!$A$1, ), IF(COUNTIF(Lucas!$A$3:$A$5506, A19), Lucas!$A$1, ), IF(COUNTIF(Will!$A$3:$A$5506, A19), Will!$A$1, ) ) -> ANGELA
A20: =IFERROR(__xludf.DUMMYFUNCTION("""COMPUTED_VALUE"""),"Yoko ono") -> Yoko ono | B20: =TEXTJOIN(", ", TRUE, IF(COUNTIF(Angela!$A$3:$A$5506, A20), Angela!$A$1, ), IF(COUNTIF(Rayreis!$A$3:$A$5506, A20), Rayreis!$A$1, ), IF(COUNTIF('Bruno bizarro'!$A$3:$A$5506, A20), 'Bruno bizarro'!$A$1, ), IF(COUNTIF(Bozsa!$A$3:$A$5506, A20), Bozsa!$A$1, ), IF(COUNTIF(Felipe!$A$3:$A$5506, A20), Felipe!$A$1, ), IF(COUNTIF(Luan!$A$3:$A$5506, A20), Luan!$A$1, ), IF(COUNTIF(Ray!$A$3:$A$5506, A20), Ray!$A$1, ), IF(COUNTIF(Raul!$A$3:$A$5506, A20), Raul!$A$1, ), IF(COUNTIF(Ricardo!$A$3:$A$5506, A20), Ricardo!$A$1, ), IF(COUNTIF(pixote!$A$3:$A$5506, A20), pixote!$A$1, ), IF(COUNTIF(Lucas!$A$3:$A$5506, A20), Lucas!$A$1, ), IF(COUNTIF(Will!$A$3:$A$5506, A20), Will!$A$1, ) ) -> ANGELA
A21: =IFERROR(__xludf.DUMMYFUNCTION("""COMPUTED_VALUE"""),"Mauricio de souza") -> Mauricio de souza | B21: =TEXTJOIN(", ", TRUE, IF(COUNTIF(Angela!$A$3:$A$5506, A21), Angela!$A$1, ), IF(COUNTIF(Rayreis!$A$3:$A$5506, A21), Rayreis!$A$1, ), IF(COUNTIF('Bruno bizarro'!$A$3:$A$5506, A21), 'Bruno bizarro'!$A$1, ), IF(COUNTIF(Bozsa!$A$3:$A$5506, A21), Bozsa!$A$1, ), IF(COUNTIF(Felipe!$A$3:$A$5506, A21), Felipe!$A$1, ), IF(COUNTIF(Luan!$A$3:$A$5506, A21), Luan!$A$1, ), IF(COUNTIF(Ray!$A$3:$A$5506, A21), Ray!$A$1, ), IF(COUNTIF(Raul!$A$3:$A$5506, A21), Raul!$A$1, ), IF(COUNTIF(Ricardo!$A$3:$A$5506, A21), Ricardo!$A$1, ), IF(COUNTIF(pixote!$A$3:$A$5506, A21), pixote!$A$1, ), IF(COUNTIF(Lucas!$A$3:$A$5506, A21), Lucas!$A$1, ), IF(COUNTIF(Will!$A$3:$A$5506, A21), Will!$A$1, ) ) -> ANGELA
A22: =IFERROR(__xludf.DUMMYFUNCTION("""COMPUTED_VALUE"""),"Raul gil") -> Raul gil | B22: =TEXTJOIN(", ", TRUE, IF(COUNTIF(Angela!$A$3:$A$5506, A22), Angela!$A$1, ), IF(COUNTIF(Rayreis!$A$3:$A$5506, A22), Rayreis!$A$1, ), IF(COUNTIF('Bruno bizarro'!$A$3:$A$5506, A22), 'Bruno bizarro'!$A$1, ), IF(COUNTIF(Bozsa!$A$3:$A$5506, A22), Bozsa!$A$1, ), IF(COUNTIF(Felipe!$A$3:$A$5506, A22), Felipe!$A$1, ), IF(COUNTIF(Luan!$A$3:$A$5506, A22), Luan!$A$1, ), IF(COUNTIF(Ray!$A$3:$A$5506, A22), Ray!$A$1, ), IF(COUNTIF(Raul!$A$3:$A$5506, A22), Raul!$A$1, ), IF(COUNTIF(Ricardo!$A$3:$A$5506, A22), Ricardo!$A$1, ), IF(COUNTIF(pixote!$A$3:$A$5506, A22), pixote!$A$1, ), IF(COUNTIF(Lucas!$A$3:$A$5506, A22), Lucas!$A$1, ), IF(COUNTIF(Will!$A$3:$A$5506, A22), Will!$A$1, ) ) -> Ray satanista, RAUL (ex-Coveiro) , Pixote, WILL
A23: =IFERROR(__xludf.DUMMYFUNCTION("""COMPUTED_VALUE"""),"Lula") -> Lula | B23: =TEXTJOIN(", ", TRUE, IF(COUNTIF(Angela!$A$3:$A$5506, A23), Angela!$A$1, ), IF(COUNTIF(Rayreis!$A$3:$A$5506, A23), Rayreis!$A$1, ), IF(COUNTIF('Bruno bizarro'!$A$3:$A$5506, A23), 'Bruno bizarro'!$A$1, ), IF(COUNTIF(Bozsa!$A$3:$A$5506, A23), Bozsa!$A$1, ), IF(COUNTIF(Felipe!$A$3:$A$5506, A23), Felipe!$A$1, ), IF(COUNTIF(Luan!$A$3:$A$5506, A23), Luan!$A$1, ), IF(COUNTIF(Ray!$A$3:$A$5506, A23), Ray!$A$1, ), IF(COUNTIF(Raul!$A$3:$A$5506, A23), Raul!$A$1, ), IF(COUNTIF(Ricardo!$A$3:$A$5506, A23), Ricardo!$A$1, ), IF(COUNTIF(pixote!$A$3:$A$5506, A23), pixote!$A$1, ), IF(COUNTIF(Lucas!$A$3:$A$5506, A23), Lucas!$A$1, ), IF(COUNTIF(Will!$A$3:$A$5506, A23), Will!$A$1, ) ) -> Ray satanista, Bruno bizarro (letra ruim), Felipe, Luan viado, Pixote
A24: =IFERROR(__xludf.DUMMYFUNCTION("""COMPUTED_VALUE"""),"Gloria menezes") -> Gloria menezes | B24: =TEXTJOIN(", ", TRUE, IF(COUNTIF(Angela!$A$3:$A$5506, A24), Angela!$A$1, ), IF(COUNTIF(Rayreis!$A$3:$A$5506, A24), Rayreis!$A$1, ), IF(COUNTIF('Bruno bizarro'!$A$3:$A$5506, A24), 'Bruno bizarro'!$A$1, ), IF(COUNTIF(Bozsa!$A$3:$A$5506, A24), Bozsa!$A$1, ), IF(COUNTIF(Felipe!$A$3:$A$5506, A24), Felipe!$A$1, ), IF(COUNTIF(Luan!$A$3:$A$5506, A24), Luan!$A$1, ), IF(COUNTIF(Ray!$A$3:$A$5506, A24), Ray!$A$1, ), IF(COUNTIF(Raul!$A$3:$A$5506, A24), Raul!$A$1, ), IF(COUNTIF(Ricardo!$A$3:$A$5506, A24), Ricardo!$A$1, ), IF(COUNTIF(pixote!$A$3:$A$5506, A24), pixote!$A$1, ), IF(COUNTIF(Lucas!$A$3:$A$5506, A24), Lucas!$A$1, ), IF(COUNTIF(Will!$A$3:$A$5506, A24), Will!$A$1, ) ) -> Ray satanista, BOZSA, RAY, WILL
A25: =IFERROR(__xludf.DUMMYFUNCTION("""COMPUTED_VALUE"""),"tony rmos") -> tony rmos | B25: =TEXTJOIN(", ", TRUE, IF(COUNTIF(Angela!$A$3:$A$5506, A25), Angela!$A$1, ), IF(COUNTIF(Rayreis!$A$3:$A$5506, A25), Rayreis!$A$1, ), IF(COUNTIF('Bruno bizarro'!$A$3:$A$5506, A25), 'Bruno bizarro'!$A$1, ), IF(COUNTIF(Bozsa!$A$3:$A$5506, A25), Bozsa!$A$1, ), IF(COUNTIF(Felipe!$A$3:$A$5506, A25), Felipe!$A$1, ), IF(COUNTIF(Luan!$A$3:$A$5506, A25), Luan!$A$1, ), IF(COUNTIF(Ray!$A$3:$A$5506, A25), Ray!$A$1, ), IF(COUNTIF(Raul!$A$3:$A$5506, A25), Raul!$A$1, ), IF(COUNTIF(Ricardo!$A$3:$A$5506, A25), Ricardo!$A$1, ), IF(COUNTIF(pixote!$A$3:$A$5506, A25), pixote!$A$1, ), IF(COUNTIF(Lucas!$A$3:$A$5506, A25), Lucas!$A$1, ), IF(COUNTIF(Will!$A$3:$A$5506, A25), Will!$A$1, ) ) -> Ray satanista
A26: =IFERROR(__xludf.DUMMYFUNCTION("""COMPUTED_VALUE"""),"lima duarte") -> lima duarte | B26: =TEXTJOIN(", ", TRUE, IF(COUNTIF(Angela!$A$3:$A$5506, A26), Angela!$A$1, ), IF(COUNTIF(Rayreis!$A$3:$A$5506, A26), Rayreis!$A$1, ), IF(COUNTIF('Bruno bizarro'!$A$3:$A$5506, A26), 'Bruno bizarro'!$A$1, ), IF(COUNTIF(Bozsa!$A$3:$A$5506, A26), Bozsa!$A$1, ), IF(COUNTIF(Felipe!$A$3:$A$5506, A26), Felipe!$A$1, ), IF(COUNTIF(Luan!$A$3:$A$5506, A26), Luan!$A$1, ), IF(COUNTIF(Ray!$A$3:$A$5506, A26), Ray!$A$1, ), IF(COUNTIF(Raul!$A$3:$A$5506, A26), Raul!$A$1, ), IF(COUNTIF(Ricardo!$A$3:$A$5506, A26), Ricardo!$A$1, ), IF(COUNTIF(pixote!$A$3:$A$5506, A26), pixote!$A$1, ), IF(COUNTIF(Lucas!$A$3:$A$5506, A26), Lucas!$A$1, ), IF(COUNTIF(Will!$A$3:$A$5506, A26), Will!$A$1, ) ) -> Ray satanista, BOZSA, Felipe, Luan viado, RAY, RAUL (ex-Coveiro) , Ricardo (Coveiro), Pixote, WILL
A27: =IFERROR(__xludf.DUMMYFUNCTION("""COMPUTED_VALUE"""),"moon taeil") -> moon taeil | B27: =TEXTJOIN(", ", TRUE, IF(COUNTIF(Angela!$A$3:$A$5506, A27), Angela!$A$1, ), IF(COUNTIF(Rayreis!$A$3:$A$5506, A27), Rayreis!$A$1, ), IF(COUNTIF('Bruno bizarro'!$A$3:$A$5506, A27), 'Bruno bizarro'!$A$1, ), IF(COUNTIF(Bozsa!$A$3:$A$5506, A27), Bozsa!$A$1, ), IF(COUNTIF(Felipe!$A$3:$A$5506, A27), Felipe!$A$1, ), IF(COUNTIF(Luan!$A$3:$A$5506, A27), Luan!$A$1, ), IF(COUNTIF(Ray!$A$3:$A$5506, A27), Ray!$A$1, ), IF(COUNTIF(Raul!$A$3:$A$5506, A27), Raul!$A$1, ), IF(COUNTIF(Ricardo!$A$3:$A$5506, A27), Ricardo!$A$1, ), IF(COUNTIF(pixote!$A$3:$A$5506, A27), pixote!$A$1, ), IF(COUNTIF(Lucas!$A$3:$A$5506, A27), Lucas!$A$1, ), IF(COUNTIF(Will!$A$3:$A$5506, A27), Will!$A$1, ) ) -> Ray satanista
A28: =IFERROR(__xludf.DUMMYFUNCTION("""COMPUTED_VALUE"""),"P diddy") -> P diddy | B28: =TEXTJOIN(", ", TRUE, IF(COUNTIF(Angela!$A$3:$A$5506, A28), Angela!$A$1, ), IF(COUNTIF(Rayreis!$A$3:$A$5506, A28), Rayreis!$A$1, ), IF(COUNTIF('Bruno bizarro'!$A$3:$A$5506, A28), 'Bruno bizarro'!$A$1, ), IF(COUNTIF(Bozsa!$A$3:$A$5506, A28), Bozsa!$A$1, ), IF(COUNTIF(Felipe!$A$3:$A$5506, A28), Felipe!$A$1, ), IF(COUNTIF(Luan!$A$3:$A$5506, A28), Luan!$A$1, ), IF(COUNTIF(Ray!$A$3:$A$5506, A28), Ray!$A$1, ), IF(COUNTIF(Raul!$A$3:$A$5506, A28), Raul!$A$1, ), IF(COUNTIF(Ricardo!$A$3:$A$5506, A28), Ricardo!$A$1, ), IF(COUNTIF(pixote!$A$3:$A$5506, A28), pixote!$A$1, ), IF(COUNTIF(Lucas!$A$3:$A$5506, A28), Lucas!$A$1, ), IF(COUNTIF(Will!$A$3:$A$5506, A28), Will!$A$1, ) ) -> Ray satanista, Lucas aleatório
A29: =IFERROR(__xludf.DUMMYFUNCTION("""COMPUTED_VALUE"""),"JK rowling") -> JK rowling | B29: =TEXTJOIN(", ", TRUE, IF(COUNTIF(Angela!$A$3:$A$5506, A29), Angela!$A$1, ), IF(COUNTIF(Rayreis!$A$3:$A$5506, A29), Rayreis!$A$1, ), IF(COUNTIF('Bruno bizarro'!$A$3:$A$5506, A29), 'Bruno bizarro'!$A$1, ), IF(COUNTIF(Bozsa!$A$3:$A$5506, A29), Bozsa!$A$1, ), IF(COUNTIF(Felipe!$A$3:$A$5506, A29), Felipe!$A$1, ), IF(COUNTIF(Luan!$A$3:$A$5506, A29), Luan!$A$1, ), IF(COUNTIF(Ray!$A$3:$A$5506, A29), Ray!$A$1, ), IF(COUNTIF(Raul!$A$3:$A$5506, A29), Raul!$A$1, ), IF(COUNTIF(Ricardo!$A$3:$A$5506, A29), Ricardo!$A$1, ), IF(COUNTIF(pixote!$A$3:$A$5506, A29), pixote!$A$1, ), IF(COUNTIF(Lucas!$A$3:$A$5506, A29), Lucas!$A$1, ), IF(COUNTIF(Will!$A$3:$A$5506, A29), Will!$A$1, ) ) -> Ray satanista
A30: =IFERROR(__xludf.DUMMYFUNCTION("""COMPUTED_VALUE"""),"jim carrey") -> jim carrey | B30: =TEXTJOIN(", ", TRUE, IF(COUNTIF(Angela!$A$3:$A$5506, A30), Angela!$A$1, ), IF(COUNTIF(Rayreis!$A$3:$A$5506, A30), Rayreis!$A$1, ), IF(COUNTIF('Bruno bizarro'!$A$3:$A$5506, A30), 'Bruno bizarro'!$A$1, ), IF(COUNTIF(Bozsa!$A$3:$A$5506, A30), Bozsa!$A$1, ), IF(COUNTIF(Felipe!$A$3:$A$5506, A30), Felipe!$A$1, ), IF(COUNTIF(Luan!$A$3:$A$5506, A30), Luan!$A$1, ), IF(COUNTIF(Ray!$A$3:$A$5506, A30), Ray!$A$1, ), IF(COUNTIF(Raul!$A$3:$A$5506, A30), Raul!$A$1, ), IF(COUNTIF(Ricardo!$A$3:$A$5506, A30), Ricardo!$A$1, ), IF(COUNTIF(pixote!$A$3:$A$5506, A30), pixote!$A$1, ), IF(COUNTIF(Lucas!$A$3:$A$5506, A30), Lucas!$A$1, ), IF(COUNTIF(Will!$A$3:$A$5506, A30), Will!$A$1, ) ) -> Ray satanista
A31: =IFERROR(__xludf.DUMMYFUNCTION("""COMPUTED_VALUE"""),"faustão") -> faustão | B31: =TEXTJOIN(", ", TRUE, IF(COUNTIF(Angela!$A$3:$A$5506, A31), Angela!$A$1, ), IF(COUNTIF(Rayreis!$A$3:$A$5506, A31), Rayreis!$A$1, ), IF(COUNTIF('Bruno bizarro'!$A$3:$A$5506, A31), 'Bruno bizarro'!$A$1, ), IF(COUNTIF(Bozsa!$A$3:$A$5506, A31), Bozsa!$A$1, ), IF(COUNTIF(Felipe!$A$3:$A$5506, A31), Felipe!$A$1, ), IF(COUNTIF(Luan!$A$3:$A$5506, A31), Luan!$A$1, ), IF(COUNTIF(Ray!$A$3:$A$5506, A31), Ray!$A$1, ), IF(COUNTIF(Raul!$A$3:$A$5506, A31), Raul!$A$1, ), IF(COUNTIF(Ricardo!$A$3:$A$5506, A31), Ricardo!$A$1, ), IF(COUNTIF(pixote!$A$3:$A$5506, A31), pixote!$A$1, ), IF(COUNTIF(Lucas!$A$3:$A$5506, A31), Lucas!$A$1, ), IF(COUNTIF(Will!$A$3:$A$5506, A31), Will!$A$1, ) ) -> Ray satanista, RAUL (ex-Coveiro) , Ricardo (Coveiro), Pixote
A32: =IFERROR(__xludf.DUMMYFUNCTION("""COMPUTED_VALUE"""),"didi") -> didi | B32: =TEXTJOIN(", ", TRUE, IF(COUNTIF(Angela!$A$3:$A$5506, A32), Angela!$A$1, ), IF(COUNTIF(Rayreis!$A$3:$A$5506, A32), Rayreis!$A$1, ), IF(COUNTIF('Bruno bizarro'!$A$3:$A$5506, A32), 'Bruno bizarro'!$A$1, ), IF(COUNTIF(Bozsa!$A$3:$A$5506, A32), Bozsa!$A$1, ), IF(COUNTIF(Felipe!$A$3:$A$5506, A32), Felipe!$A$1, ), IF(COUNTIF(Luan!$A$3:$A$5506, A32), Luan!$A$1, ), IF(COUNTIF(Ray!$A$3:$A$5506, A32), Ray!$A$1, ), IF(COUNTIF(Raul!$A$3:$A$5506, A32), Raul!$A$1, ), IF(COUNTIF(Ricardo!$A$3:$A$5506, A32), Ricardo!$A$1, ), IF(COUNTIF(pixote!$A$3:$A$5506, A32), pixote!$A$1, ), IF(COUNTIF(Lucas!$A$3:$A$5506, A32), Lucas!$A$1, ), IF(COUNTIF(Will!$A$3:$A$5506, A32), Will!$A$1, ) ) -> Ray satanista, RAUL (ex-Coveiro)
A33: =IFERROR(__xludf.DUMMYFUNCTION("""COMPUTED_VALUE"""),"neil gayman") -> neil gayman | B33: =TEXTJOIN(", ", TRUE, IF(COUNTIF(Angela!$A$3:$A$5506, A33), Angela!$A$1, ), IF(COUNTIF(Rayreis!$A$3:$A$5506, A33), Rayreis!$A$1, ), IF(COUNTIF('Bruno bizarro'!$A$3:$A$5506, A33), 'Bruno bizarro'!$A$1, ), IF(COUNTIF(Bozsa!$A$3:$A$5506, A33), Bozsa!$A$1, ), IF(COUNTIF(Felipe!$A$3:$A$5506, A33), Felipe!$A$1, ), IF(COUNTIF(Luan!$A$3:$A$5506, A33), Luan!$A$1, ), IF(COUNTIF(Ray!$A$3:$A$5506, A33), Ray!$A$1, ), IF(COUNTIF(Raul!$A$3:$A$5506, A33), Raul!$A$1, ), IF(COUNTIF(Ricardo!$A$3:$A$5506, A33), Ricardo!$A$1, ), IF(COUNTIF(pixote!$A$3:$A$5506, A33), pixote!$A$1, ), IF(COUNTIF(Lucas!$A$3:$A$5506, A33), Lucas!$A$1, ), IF(COUNTIF(Will!$A$3:$A$5506, A33), Will!$A$1, ) ) -> Ray satanista
A34: =IFERROR(__xludf.DUMMYFUNCTION("""COMPUTED_VALUE"""),"Dinho ouro preto") -> Dinho ouro preto | B34: =TEXTJOIN(", ", TRUE, IF(COUNTIF(Angela!$A$3:$A$5506, A34), Angela!$A$1, ), IF(COUNTIF(Rayreis!$A$3:$A$5506, A34), Rayreis!$A$1, ), IF(COUNTIF('Bruno bizarro'!$A$3:$A$5506, A34), 'Bruno bizarro'!$A$1, ), IF(COUNTIF(Bozsa!$A$3:$A$5506, A34), Bozsa!$A$1, ), IF(COUNTIF(Felipe!$A$3:$A$5506, A34), Felipe!$A$1, ), IF(COUNTIF(Luan!$A$3:$A$5506, A34), Luan!$A$1, ), IF(COUNTIF(Ray!$A$3:$A$5506, A34), Ray!$A$1, ), IF(COUNTIF(Raul!$A$3:$A$5506, A34), Raul!$A$1, ), IF(COUNTIF(Ricardo!$A$3:$A$5506, A34), Ricardo!$A$1, ), IF(COUNTIF(pixote!$A$3:$A$5506, A34), pixote!$A$1, ), IF(COUNTIF(Lucas!$A$3:$A$5506, A34), Lucas!$A$1, ), IF(COUNTIF(Will!$A$3:$A$5506, A34), Will!$A$1, ) ) -> Ray satanista
A35: =IFERROR(__xludf.DUMMYFUNCTION("""COMPUTED_VALUE"""),"Andressa urach") -> Andressa urach | B35: =TEXTJOIN(", ", TRUE, IF(COUNTIF(Angela!$A$3:$A$5506, A35), Angela!$A$1, ), IF(COUNTIF(Rayreis!$A$3:$A$5506, A35), Rayreis!$A$1, ), IF(COUNTIF('Bruno bizarro'!$A$3:$A$5506, A35), 'Bruno bizarro'!$A$1, ), IF(COUNTIF(Bozsa!$A$3:$A$5506, A35), Bozsa!$A$1, ), IF(COUNTIF(Felipe!$A$3:$A$5506, A35), Felipe!$A$1, ), IF(COUNTIF(Luan!$A$3:$A$5506, A35), Luan!$A$1, ), IF(COUNTIF(Ray!$A$3:$A$5506, A35), Ray!$A$1, ), IF(COUNTIF(Raul!$A$3:$A$5506, A35), Raul!$A$1, ), IF(COUNTIF(Ricardo!$A$3:$A$5506, A35), Ricardo!$A$1, ), IF(COUNTIF(pixote!$A$3:$A$5506, A35), pixote!$A$1, ), IF(COUNTIF(Lucas!$A$3:$A$5506, A35), Lucas!$A$1, ), IF(COUNTIF(Will!$A$3:$A$5506, A35), Will!$A$1, ) ) -> Ray satanista, WILL
A36: =IFERROR(__xludf.DUMMYFUNCTION("""COMPUTED_VALUE"""),"Yoon suk yeel") -> Yoon suk yeel | B36: =TEXTJOIN(", ", TRUE, IF(COUNTIF(Angela!$A$3:$A$5506, A36), Angela!$A$1, ), IF(COUNTIF(Rayreis!$A$3:$A$5506, A36), Rayreis!$A$1, ), IF(COUNTIF('Bruno bizarro'!$A$3:$A$5506, A36), 'Bruno bizarro'!$A$1, ), IF(COUNTIF(Bozsa!$A$3:$A$5506, A36), Bozsa!$A$1, ), IF(COUNTIF(Felipe!$A$3:$A$5506, A36), Felipe!$A$1, ), IF(COUNTIF(Luan!$A$3:$A$5506, A36), Luan!$A$1, ), IF(COUNTIF(Ray!$A$3:$A$5506, A36), Ray!$A$1, ), IF(COUNTIF(Raul!$A$3:$A$5506, A36), Raul!$A$1, ), IF(COUNTIF(Ricardo!$A$3:$A$5506, A36), Ricardo!$A$1, ), IF(COUNTIF(pixote!$A$3:$A$5506, A36), pixote!$A$1, ), IF(COUNTIF(Lucas!$A$3:$A$5506, A36), Lucas!$A$1, ), IF(COUNTIF(Will!$A$3:$A$5506, A36), Will!$A$1, ) ) -> Ray satanista
A37: =IFERROR(__xludf.DUMMYFUNCTION("""COMPUTED_VALUE"""),"Zizi pessi") -> Zizi pessi | B37: =TEXTJOIN(", ", TRUE, IF(COUNTIF(Angela!$A$3:$A$5506, A37), Angela!$A$1, ), IF(COUNTIF(Rayreis!$A$3:$A$5506, A37), Rayreis!$A$1, ), IF(COUNTIF('Bruno bizarro'!$A$3:$A$5506, A37), 'Bruno bizarro'!$A$1, ), IF(COUNTIF(Bozsa!$A$3:$A$5506, A37), Bozsa!$A$1, ), IF(COUNTIF(Felipe!$A$3:$A$5506, A37), Felipe!$A$1, ), IF(COUNTIF(Luan!$A$3:$A$5506, A37), Luan!$A$1, ), IF(COUNTIF(Ray!$A$3:$A$5506, A37), Ray!$A$1, ), IF(COUNTIF(Raul!$A$3:$A$5506, A37), Raul!$A$1, ), IF(COUNTIF(Ricardo!$A$3:$A$5506, A37), Ricardo!$A$1, ), IF(COUNTIF(pixote!$A$3:$A$5506, A37), pixote!$A$1, ), IF(COUNTIF(Lucas!$A$3:$A$5506, A37), Lucas!$A$1, ), IF(COUNTIF(Will!$A$3:$A$5506, A37), Will!$A$1, ) ) -> Ray satanista
A38: =IFERROR(__xludf.DUMMYFUNCTION("""COMPUTED_VALUE"""),"Joe biden") -> Joe biden | B38: =TEXTJOIN(", ", TRUE, IF(COUNTIF(Angela!$A$3:$A$5506, A38), Angela!$A$1, ), IF(COUNTIF(Rayreis!$A$3:$A$5506, A38), Rayreis!$A$1, ), IF(COUNTIF('Bruno bizarro'!$A$3:$A$5506, A38), 'Bruno bizarro'!$A$1, ), IF(COUNTIF(Bozsa!$A$3:$A$5506, A38), Bozsa!$A$1, ), IF(COUNTIF(Felipe!$A$3:$A$5506, A38), Felipe!$A$1, ), IF(COUNTIF(Luan!$A$3:$A$5506, A38), Luan!$A$1, ), IF(COUNTIF(Ray!$A$3:$A$5506, A38), Ray!$A$1, ), IF(COUNTIF(Raul!$A$3:$A$5506, A38), Raul!$A$1, ), IF(COUNTIF(Ricardo!$A$3:$A$5506, A38), Ricardo!$A$1, ), IF(COUNTIF(pixote!$A$3:$A$5506, A38), pixote!$A$1, ), IF(COUNTIF(Lucas!$A$3:$A$5506, A38), Lucas!$A$1, ), IF(COUNTIF(Will!$A$3:$A$5506, A38), Will!$A$1, ) ) -> Ray satanista
A39: =IFERROR(__xludf.DUMMYFUNCTION("""COMPUTED_VALUE"""),"leonardo cantor") -> leonardo cantor | B39: =TEXTJOIN(", ", TRUE, IF(COUNTIF(Angela!$A$3:$A$5506, A39), Angela!$A$1, ), IF(COUNTIF(Rayreis!$A$3:$A$5506, A39), Rayreis!$A$1, ), IF(COUNTIF('Bruno bizarro'!$A$3:$A$5506, A39), 'Bruno bizarro'!$A$1, ), IF(COUNTIF(Bozsa!$A$3:$A$5506, A39), Bozsa!$A$1, ), IF(COUNTIF(Felipe!$A$3:$A$5506, A39), Felipe!$A$1, ), IF(COUNTIF(Luan!$A$3:$A$5506, A39), Luan!$A$1, ), IF(COUNTIF(Ray!$A$3:$A$5506, A39), Ray!$A$1, ), IF(COUNTIF(Raul!$A$3:$A$5506, A39), Raul!$A$1, ), IF(COUNTIF(Ricardo!$A$3:$A$5506, A39), Ricardo!$A$1, ), IF(COUNTIF(pixote!$A$3:$A$5506, A39), pixote!$A$1, ), IF(COUNTIF(Lucas!$A$3:$A$5506, A39), Lucas!$A$1, ), IF(COUNTIF(Will!$A$3:$A$5506, A39), Will!$A$1, ) ) -> Ray satanista
A40: =IFERROR(__xludf.DUMMYFUNCTION("""COMPUTED_VALUE"""),"Maiaria da maraisa") -> Maiaria da maraisa | B40: =TEXTJOIN(", ", TRUE, IF(COUNTIF(Angela!$A$3:$A$5506, A40), Angela!$A$1, ), IF(COUNTIF(Rayreis!$A$3:$A$5506, A40), Rayreis!$A$1, ), IF(COUNTIF('Bruno bizarro'!$A$3:$A$5506, A40), 'Bruno bizarro'!$A$1, ), IF(COUNTIF(Bozsa!$A$3:$A$5506, A40), Bozsa!$A$1, ), IF(COUNTIF(Felipe!$A$3:$A$5506, A40), Felipe!$A$1, ), IF(COUNTIF(Luan!$A$3:$A$5506, A40), Luan!$A$1, ), IF(COUNTIF(Ray!$A$3:$A$5506, A40), Ray!$A$1, ), IF(COUNTIF(Raul!$A$3:$A$5506, A40), Raul!$A$1, ), IF(COUNTIF(Ricardo!$A$3:$A$5506, A40), Ricardo!$A$1, ), IF(COUNTIF(pixote!$A$3:$A$5506, A40), pixote!$A$1, ), IF(COUNTIF(Lucas!$A$3:$A$5506, A40), Lucas!$A$1, ), IF(COUNTIF(Will!$A$3:$A$5506, A40), Will!$A$1, ) ) -> Ray satanista
...
